Workbook

Sheet Dados
A1: Amostra | B1: Tabela | C1: Grupo | D1: Furo | E1: Profundidade (m)* | F1: U3O8 total (ppm) | G1: U3O8 solúvel (ppm) | H1: U3O8 fixo (ppm) | I1: ThO2 (ppm, como reportado) | J1: ThO2 numérico (ppm) | K1: % solúvel | L1: ThO2/U3O8 | M1: |U − mediana fundo| (aux.)
A2: CV03 | B2: 1 | C2: Superfície | D2: CV (superfície) | E2: 0 | F2: 8 | I2: <100 | K2: =IF(G2="","",G2/F2) | L2: =IF(J2="","",J2/F2) | M2: =ABS(F2-MEDIAN($F$2:$F$27)) -> 0.5
A3: CV07 | B3: 1 | C3: Superfície | D3: CV (superfície) | E3: 0 | F3: 7 | G3: 4.8 | H3: 2.2 | I3: <100 | K3: =IF(G3="","",G3/F3) -> 0.68571429 | L3: =IF(J3="","",J3/F3) | M3: =ABS(F3-MEDIAN($F$2:$F$27)) -> 1.5
A4: CV07A | B4: 1 | C4: Superfície | D4: CV (superfície) | E4: 0 | F4: 9 | G4: 7.12 | H4: 1.88 | I4: <100 | K4: =IF(G4="","",G4/F4) -> 0.79111111 | L4: =IF(J4="","",J4/F4) | M4: =ABS(F4-MEDIAN($F$2:$F$27)) -> 0.5
A5: CV11 | B5: 1 | C5: Superfície | D5: CV (superfície) | E5: 0 | F5: 5 | G5: 1.5 | H5: 3.5 | I5: <100 | K5: =IF(G5="","",G5/F5) -> 0.3 | L5: =IF(J5="","",J5/F5) | M5: =ABS(F5-MEDIAN($F$2:$F$27)) -> 3.5
A6: CV17 | B6: 1 | C6: Superfície | D6: CV (superfície) | E6: 0 | F6: 11 | G6: 6.2 | H6: 4.8 | I6: <100 | K6: =IF(G6="","",G6/F6) -> 0.56363636 | L6: =IF(J6="","",J6/F6) | M6: =ABS(F6-MEDIAN($F$2:$F$27)) -> 2.5
A7: CV17A | B7: 1 | C7: Superfície | D7: CV (superfície) | E7: 0 | F7: 12 | G7: 8.04 | H7: 3.96 | I7: <100 | K7: =IF(G7="","",G7/F7) -> 0.67 | L7: =IF(J7="","",J7/F7) | M7: =ABS(F7-MEDIAN($F$2:$F$27)) -> 3.5
A8: CV25 | B8: 1 | C8: Superfície | D8: CV (superfície) | E8: 0 | F8: 9 | G8: 2.7 | H8: 6.3 | I8: <100 | K8: =IF(G8="","",G8/F8) -> 0.3 | L8: =IF(J8="","",J8/F8) | M8: =ABS(F8-MEDIAN($F$2:$F$27)) -> 0.5
A9: F1 33,90 | B9: 1 | C9: Subsuperfície | D9: F1 | E9: 33.9 | F9: 4 | G9: 3.29 | H9: 0.71 | I9: <100 | K9: =IF(G9="","",G9/F9) -> 0.8225 | L9: =IF(J9="","",J9/F9) | M9: =ABS(F9-MEDIAN($F$2:$F$27)) -> 4.5
A10: F2 37,85 | B10: 1 | C10: Subsuperfície | D10: F2 | E10: 37.85 | F10: 10 | G10: 4.19 | H10: 5.81 | I10: <100 | K10: =IF(G10="","",G10/F10) -> 0.419 | L10: =IF(J10="","",J10/F10) | M10: =ABS(F10-MEDIAN($F$2:$F$27)) -> 1.5
A11: F2 50,50 | B11: 1 | C11: Subsuperfície | D11: F2 | E11: 50.5 | F11: 7 | G11: 3.83 | H11: 3.17 | I11: <100 | K11: =IF(G11="","",G11/F11) -> 0.54714286 | L11: =IF(J11="","",J11/F11) | M11: =ABS(F11-MEDIAN($F$2:$F$27)) -> 1.5
A12: F2 63,65 | B12: 1 | C12: Subsuperfície | D12: F2 | E12: 63.65 | F12: 14 | G12: 8.02 | H12: 5.98 | I12: <100 | K12: =IF(G12="","",G12/F12) -> 0.57285714 | L12: =IF(J12="","",J12/F12) | M12: =ABS(F12-MEDIAN($F$2:$F$27)) -> 5.5
A13: F2 64,90 | B13: 1 | C13: Subsuperfície | D13: F2 | E13: 64.9 | F13: 19 | G13: 13.52 | H13: 5.48 | I13: <100 | K13: =IF(G13="","",G13/F13) -> 0.71157895 | L13: =IF(J13="","",J13/F13) | M13: =ABS(F13-MEDIAN($F$2:$F$27)) -> 10.5
A14: F2 68,90 | B14: 1 | C14: Subsuperfície | D14: F2 | E14: 68.9 | F14: 6 | G14: 3.83 | H14: 2.17 | I14: <100 | K14: =IF(G14="","",G14/F14) -> 0.63833333 | L14: =IF(J14="","",J14/F14) | M14: =ABS(F14-MEDIAN($F$2:$F$27)) -> 2.5
... A24: S8 83,25 | B24: 1 | C24: Subsuperfície | D24: S8 | E24: 83.25 | F24: 5 | G24: 3.67 | H24: 1.33 | I24: <100 | K24: =IF(G24="","",G24/F24) -> 0.734 | L24: =IF(J24="","",J24/F24) | M24: =ABS(F24-MEDIAN($F$2:$F$27)) -> 3.5
A25: S9 79,15 | B25: 1 | C25: Subsuperfície | D25: S9 | E25: 79.15 | F25: 26 | G25: 17.93 | H25: 8.07 | I25: 150 | J25: 150 | K25: =IF(G25="","",G25/F25) -> 0.68961538 | L25: =IF(J25="","",J25/F25) -> 5.7692308 | M25: =ABS(F25-MEDIAN($F$2:$F$27)) -> 17.5
A26: S9 82,70 | B26: 1 | C26: Subsuperfície | D26: S9 | E26: 82.7 | F26: 19 | G26: 18.3 | H26: 0.7 | I26: 140 | J26: 140 | K26: =IF(G26="","",G26/F26) -> 0.96315789 | L26: =IF(J26="","",J26/F26) -> 7.3684211 | M26: =ABS(F26-MEDIAN($F$2:$F$27)) -> 10.5
A27: S16 22,70 | B27: 1 | C27: Subsuperfície | D27: S16 | E27: 22.7 | F27: 7 | G27: 3.64 | H27: 3.36 | I27: <100 | K27: =IF(G27="","",G27/F27) -> 0.52 | L27: =IF(J27="","",J27/F27) | M27: =ABS(F27-MEDIAN($F$2:$F$27)) -> 1.5
A28: F1 54,80 | B28: 2 | C28: Dique félsico anômalo | D28: F1 | E28: 54.8 | F28: 56 | G28: 36.08 | H28: 19.92 | I28: 270 | J28: 270 | K28: =IF(G28="","",G28/F28) -> 0.64428571 | L28: =IF(J28="","",J28/F28) -> 4.8214286
A29: F2 77,75 | B29: 2 | C29: Dique félsico anômalo | D29: F2 | E29: 77.75 | F29: 48 | G29: 34.27 | H29: 13.73 | I29: 240 | J29: 240 | K29: =IF(G29="","",G29/F29) -> 0.71395833 | L29: =IF(J29="","",J29/F29) -> 5
A30: F7 130,15 | B30: 2 | C30: Dique félsico anômalo | D30: F7 | E30: 130.15 | F30: 30 | G30: 21.55 | H30: 8.45 | I30: 250 | J30: 250 | K30: =IF(G30="","",G30/F30) -> 0.71833333 | L30: =IF(J30="","",J30/F30) -> 8.3333333
A31: S2 114,60 | B31: 2 | C31: Dique félsico anômalo | D31: S2 | E31: 114.6 | F31: 21 | G31: 3.7 | H31: 17.3 | I31: 180 | J31: 180 | K31: =IF(G31="","",G31/F31) -> 0.17619048 | L31: =IF(J31="","",J31/F31) -> 8.5714286
A32: S3 21,35 | B32: 2 | C32: Dique félsico anômalo | D32: S3 | E32: 21.35 | F32: 18 | G32: 14.15 | H32: 3.85 | I32: 220 | J32: 220 | K32: =IF(G32="","",G32/F32) -> 0.78611111 | L32: =IF(J32="","",J32/F32) -> 12.222222
A33: S3 28,10 | B33: 2 | C33: Dique félsico anômalo | D33: S3 | E33: 28.1 | F33: 49 | G33: 29.54 | H33: 19.46 | I33: 210 | J33: 210 | K33: =IF(G33="","",G33/F33) -> 0.60285714 | L33: =IF(J33="","",J33/F33) -> 4.2857143
A34: S3 45,48 | B34: 2 | C34: Dique félsico anômalo | D34: S3 | E34: 45.48 | F34: 24 | G34: 19.11 | H34: 4.89 | I34: 240 | J34: 240 | K34: =IF(G34="","",G34/F34) -> 0.79625 | L34: =IF(J34="","",J34/F34) -> 10
A35: S3 60,50 | B35: 2 | C35: Dique félsico anômalo | D35: S3 | E35: 60.5 | F35: 36 | G35: 29.14 | H35: 6.86 | I35: 220 | J35: 220 | K35: =IF(G35="","",G35/F35) -> 0.80944444 | L35: =IF(J35="","",J35/F35) -> 6.1111111
A36: S8 141,90 | B36: 2 | C36: Dique félsico anômalo | D36: S8 | E36: 141.9 | F36: 50 | G36: 27.84 | H36: 22.16 | I36: 310 | J36: 310 | K36: =IF(G36="","",G36/F36) -> 0.5568 | L36: =IF(J36="","",J36/F36) -> 6.2
A37: S9 80,20 | B37: 2 | C37: Dique félsico anômalo | D37: S9 | E37: 80.2 | F37: 21 | G37: 15.56 | H37: 5.44 | I37: 110 | J37: 110 | K37: =IF(G37="","",G37/F37) -> 0.74095238 | L37: =IF(J37="","",J37/F37) -> 5.2380952
A38: S9 109,80 | B38: 2 | C38: Dique félsico anômalo | D38: S9 | E38: 109.8 | F38: 23 | I38: 120 | J38: 120 | K38: =IF(G38="","",G38/F38) | L38: =IF(J38="","",J38/F38) -> 5.2173913
A39: S3 16,20 | B39: 2 | C39: Dique félsico anômalo | D39: S3 | E39: 16.2 | F39: 2310 | G39: 2306.28 | H39: 3.72 | I39: 230 | J39: 230 | K39: =IF(G39="","",G39/F39) -> 0.99838961 | L39: =IF(J39="","",J39/F39) -> 0.0995671
A41: Fonte: tabelas fornecidas pela usuária (imagem). Texto azul = valor transcrito; preto = fórmula.
A42: * Profundidade inferida do código da amostra (ex.: 'F2 63,65' = furo F2, 63,65 m). CV = superfície (0 m). Confirmar com a fonte.
A43: '–' na tabela original = sem análise; células deixadas em branco (CV03 e S9 109,80 sem solúvel/fixo).
A44: ThO2 '<100' = abaixo do limite de detecção; coluna numérica deixada em branco nesses casos.
A45: Grupos: Superfície = CV (Tab. 1); Subsuperfície = F e S da Tab. 1; Dique félsico anômalo = Tab. 2 (também subsuperfície).

Sheet Estatística
A1: Estatística descritiva de U3O8 por grupo
A3: U3O8 TOTAL (ppm) | B3: Superfície (CV) | C3: Subsuperfície – Tab. 1 (F, S) | D3: Diques félsicos anômalos (Tab. 2) | E3: Diques s/ S3 16,20 | F3: Subsuperfície total | G3: Fundo: CV + Tab. 1
A4: n | B4: =COUNT(Dados!F2:F8) -> 7 | C4: =COUNT(Dados!F9:F27) -> 19 | D4: =COUNT(Dados!F28:F39) -> 12 | E4: =COUNT(Dados!F28:F38) -> 11 | F4: =COUNT(Dados!F9:F39) -> 31 | G4: =COUNT(Dados!F2:F27) -> 26
A5: Média | B5: =AVERAGE(Dados!F2:F8) -> 8.7142857 | C5: =AVERAGE(Dados!F9:F27) -> 10.368421 | D5: =AVERAGE(Dados!F28:F39) -> 223.83333 | E5: =AVERAGE(Dados!F28:F38) -> 34.181818 | F5: =AVERAGE(Dados!F9:F39) -> 93 | G5: =AVERAGE(Dados!F2:F27) -> 9.9230769
A6: Mediana | B6: =MEDIAN(Dados!F2:F8) -> 9 | C6: =MEDIAN(Dados!F9:F27) -> 8 | D6: =MEDIAN(Dados!F28:F39) -> 33 | E6: =MEDIAN(Dados!F28:F38) -> 30 | F6: =MEDIAN(Dados!F9:F39) -> 14 | G6: =MEDIAN(Dados!F2:F27) -> 8.5
A7: Média geométrica | B7: =GEOMEAN(Dados!F2:F8) -> 8.4173203 | C7: =GEOMEAN(Dados!F9:F27) -> 9.0937755 | D7: =GEOMEAN(Dados!F28:F39) -> 45.162028 | E7: =GEOMEAN(Dados!F28:F38) -> 31.580898 | F7: =GEOMEAN(Dados!F9:F39) -> 16.911218 | G7: =GEOMEAN(Dados!F2:F27) -> 8.9064791
A8: Desvio padrão | B8: =STDEV(Dados!F2:F8) -> 2.3603874 | C8: =STDEV(Dados!F9:F27) -> 5.8234252 | D8: =STDEV(Dados!F28:F39) -> 657.11018 | E8: =STDEV(Dados!F28:F38) -> 14.126699 | F8: =STDEV(Dados!F9:F39) -> 411.72329 | G8: =STDEV(Dados!F2:F27) -> 5.1297023
A9: Coef. de variação | B9: =STDEV(Dados!F2:F8)/AVERAGE(Dados!F2:F8) -> 0.27086413 | C9: =STDEV(Dados!F9:F27)/AVERAGE(Dados!F9:F27) -> 0.56165014 | D9: =STDEV(Dados!F28:F39)/AVERAGE(Dados!F28:F39) -> 2.9357119 | E9: =STDEV(Dados!F28:F38)/AVERAGE(Dados!F28:F38) -> 0.4132811 | F9: =STDEV(Dados!F9:F39)/AVERAGE(Dados!F9:F39) -> 4.4271321 | G9: =STDEV(Dados!F2:F27)/AVERAGE(Dados!F2:F27) -> 0.51694675
A10: Mínimo | B10: =MIN(Dados!F2:F8) -> 5 | C10: =MIN(Dados!F9:F27) -> 4 | D10: =MIN(Dados!F28:F39) -> 18 | E10: =MIN(Dados!F28:F38) -> 18 | F10: =MIN(Dados!F9:F39) -> 4 | G10: =MIN(Dados!F2:F27) -> 4
A11: 1º quartil | B11: =QUARTILE(Dados!F2:F8,1) -> 7.5 | C11: =QUARTILE(Dados!F9:F27,1) -> 6.5 | D11: =QUARTILE(Dados!F28:F39,1) -> 22.5 | E11: =QUARTILE(Dados!F28:F38,1) -> 22 | F11: =QUARTILE(Dados!F9:F39,1) -> 8 | G11: =QUARTILE(Dados!F2:F27,1) -> 7
A12: 3º quartil | B12: =QUARTILE(Dados!F2:F8,3) -> 10 | C12: =QUARTILE(Dados!F9:F27,3) -> 13 | D12: =QUARTILE(Dados!F28:F39,3) -> 49.25 | E12: =QUARTILE(Dados!F28:F38,3) -> 48.5 | F12: =QUARTILE(Dados!F9:F39,3) -> 25 | G12: =QUARTILE(Dados!F2:F27,3) -> 11.75
A13: Máximo | B13: =MAX(Dados!F2:F8) -> 12 | C13: =MAX(Dados!F9:F27) -> 26 | D13: =MAX(Dados!F28:F39) -> 2310 | E13: =MAX(Dados!F28:F38) -> 56 | F13: =MAX(Dados!F9:F39) -> 2310 | G13: =MAX(Dados!F2:F27) -> 26
A15: U3O8 SOLÚVEL (ppm) | B15: Superfície (CV) | C15: Subsuperfície – Tab. 1 (F, S) | D15: Diques félsicos anômalos (Tab. 2) | E15: Diques s/ S3 16,20 | F15: Subsuperfície total | G15: Fundo: CV + Tab. 1
A16: n | B16: =COUNT(Dados!G2:G8) -> 6 | C16: =COUNT(Dados!G9:G27) -> 19 | D16: =COUNT(Dados!G28:G39) -> 11 | E16: =COUNT(Dados!G28:G38) -> 10 | F16: =COUNT(Dados!G9:G39) -> 30 | G16: =COUNT(Dados!G2:G27) -> 25
A17: Média | B17: =AVERAGE(Dados!G2:G8) -> 5.06 | C17: =AVERAGE(Dados!G9:G27) -> 7.4257895 | D17: =AVERAGE(Dados!G28:G39) -> 230.65636 | E17: =AVERAGE(Dados!G28:G38) -> 23.094 | F17: =AVERAGE(Dados!G9:G39) -> 89.277 | G17: =AVERAGE(Dados!G2:G27) -> 6.858
A18: Mediana | B18: =MEDIAN(Dados!G2:G8) -> 5.5 | C18: =MEDIAN(Dados!G9:G27) -> 5.67 | D18: =MEDIAN(Dados!G28:G39) -> 27.84 | E18: =MEDIAN(Dados!G28:G38) -> 24.695 | F18: =MEDIAN(Dados!G9:G39) -> 8.9 | G18: =MEDIAN(Dados!G2:G27) -> 5.67
A19: Média geométrica | B19: =GEOMEAN(Dados!G2:G8) -> 4.3631887 | C19: =GEOMEAN(Dados!G9:G27) -> 6.2891868 | D19: =GEOMEAN(Dados!G28:G39) -> 30.711669 | E19: =GEOMEAN(Dados!G28:G38) -> 19.940799 | F19: =GEOMEAN(Dados!G9:G39) -> 11.249186 | G19: =GEOMEAN(Dados!G2:G27) -> 5.7608262
A20: Desvio padrão | B20: =STDEV(Dados!G2:G8) -> 2.5586872 | C20: =STDEV(Dados!G9:G27) -> 4.8302131 | D20: =STDEV(Dados!G28:G39) -> 688.47368 | E20: =STDEV(Dados!G28:G38) -> 10.139628 | F20: =STDEV(Dados!G9:G39) -> 418.84662 | G20: =STDEV(Dados!G2:G27) -> 4.4638072
A21: Coef. de variação | B21: =STDEV(Dados!G2:G8)/AVERAGE(Dados!G2:G8) -> 0.5056694 | C21: =STDEV(Dados!G9:G27)/AVERAGE(Dados!G9:G27) -> 0.6504646 | D21: =STDEV(Dados!G28:G39)/AVERAGE(Dados!G28:G39) -> 2.9848458 | E21: =STDEV(Dados!G28:G38)/AVERAGE(Dados!G28:G38) -> 0.43905896 | F21: =STDEV(Dados!G9:G39)/AVERAGE(Dados!G9:G39) -> 4.69154 | G21: =STDEV(Dados!G2:G27)/AVERAGE(Dados!G2:G27) -> 0.65089053
A22: Mínimo | B22: =MIN(Dados!G2:G8) -> 1.5 | C22: =MIN(Dados!G9:G27) -> 3.29 | D22: =MIN(Dados!G28:G39) -> 3.7 | E22: =MIN(Dados!G28:G38) -> 3.7 | F22: =MIN(Dados!G9:G39) -> 3.29 | G22: =MIN(Dados!G2:G27) -> 1.5
A23: 1º quartil | B23: =QUARTILE(Dados!G2:G8,1) -> 3.225 | C23: =QUARTILE(Dados!G9:G27,1) -> 3.83 | D23: =QUARTILE(Dados!G28:G39,1) -> 17.335 | E23: =QUARTILE(Dados!G28:G38,1) -> 16.4475 | F23: =QUARTILE(Dados!G9:G39,1) -> 4.2475 | G23: =QUARTILE(Dados!G2:G27,1) -> 3.83
A24: 3º quartil | B24: =QUARTILE(Dados!G2:G8,3) -> 6.89 | C24: =QUARTILE(Dados!G9:G27,3) -> 8.9 | D24: =QUARTILE(Dados!G28:G39,3) -> 31.905 | E24: =QUARTILE(Dados!G28:G38,3) -> 29.44 | F24: =QUARTILE(Dados!G9:G39,3) -> 18.9075 | G24: =QUARTILE(Dados!G2:G27,3) -> 8.02
A25: Máximo | B25: =MAX(Dados!G2:G8) -> 8.04 | C25: =MAX(Dados!G9:G27) -> 18.3 | D25: =MAX(Dados!G28:G39) -> 2306.28 | E25: =MAX(Dados!G28:G38) -> 36.08 | F25: =MAX(Dados!G9:G39) -> 2306.28 | G25: =MAX(Dados!G2:G27) -> 18.3
A27: U3O8 FIXO (ppm) | B27: Superfície (CV) | C27: Subsuperfície – Tab. 1 (F, S) | D27: Diques félsicos anômalos (Tab. 2) | E27: Diques s/ S3 16,20 | F27: Subsuperfície total | G27: Fundo: CV + Tab. 1
A28: n | B28: =COUNT(Dados!H2:H8) -> 6 | C28: =COUNT(Dados!H9:H27) -> 19 | D28: =COUNT(Dados!H28:H39) -> 11 | E28: =COUNT(Dados!H28:H38) -> 10 | F28: =COUNT(Dados!H9:H39) -> 30 | G28: =COUNT(Dados!H2:H27) -> 25
A29: Média | B29: =AVERAGE(Dados!H2:H8) -> 3.7733333 | C29: =AVERAGE(Dados!H9:H27) -> 2.9426316 | D29: =AVERAGE(Dados!H28:H39) -> 11.434545 | E29: =AVERAGE(Dados!H28:H38) -> 12.206 | F29: =AVERAGE(Dados!H9:H39) -> 6.0563333 | G29: =AVERAGE(Dados!H2:H27) -> 3.142
A30: Mediana | B30: =MEDIAN(Dados!H2:H8) -> 3.73 | C30: =MEDIAN(Dados!H9:H27) -> 2.22 | D30: =MEDIAN(Dados!H28:H39) -> 8.45 | E30: =MEDIAN(Dados!H28:H38) -> 11.09 | F30: =MEDIAN(Dados!H9:H39) -> 3.785 | G30: =MEDIAN(Dados!H2:H27) -> 2.33
A31: Média geométrica | B31: =GEOMEAN(Dados!H2:H8) -> 3.4659391 | C31: =GEOMEAN(Dados!H9:H27) -> 2.2420244 | D31: =GEOMEAN(Dados!H28:H39) -> 9.3009703 | E31: =GEOMEAN(Dados!H28:H38) -> 10.193581 | F31: =GEOMEAN(Dados!H9:H39) -> 3.7774545 | G31: =GEOMEAN(Dados!H2:H27) -> 2.4891077
A32: Desvio padrão | B32: =STDEV(Dados!H2:H8) -> 1.6497111 | C32: =STDEV(Dados!H9:H27) -> 2.1532839 | D32: =STDEV(Dados!H28:H39) -> 7.1885887 | E32: =STDEV(Dados!H28:H38) -> 7.0812149 | F32: =STDEV(Dados!H9:H39) -> 6.1660972 | G32: =STDEV(Dados!H2:H27) -> 2.0434224
A33: Coef. de variação | B33: =STDEV(Dados!H2:H8)/AVERAGE(Dados!H2:H8) -> 0.43720258 | C33: =STDEV(Dados!H9:H27)/AVERAGE(Dados!H9:H27) -> 0.7317545 | D33: =STDEV(Dados!H28:H39)/AVERAGE(Dados!H28:H39) -> 0.62867289 | E33: =STDEV(Dados!H28:H38)/AVERAGE(Dados!H28:H38) -> 0.58014213 | F33: =STDEV(Dados!H9:H39)/AVERAGE(Dados!H9:H39) -> 1.0181238 | G33: =STDEV(Dados!H2:H27)/AVERAGE(Dados!H2:H27) -> 0.65035722
A34: Mínimo | B34: =MIN(Dados!H2:H8) -> 1.88 | C34: =MIN(Dados!H9:H27) -> 0.58 | D34: =MIN(Dados!H28:H39) -> 3.72 | E34: =MIN(Dados!H28:H38) -> 3.85 | F34: =MIN(Dados!H9:H39) -> 0.58 | G34: =MIN(Dados!H2:H27) -> 0.58
A35: 1º quartil | B35: =QUARTILE(Dados!H2:H8,1) -> 2.525 | C35: =QUARTILE(Dados!H9:H27,1) -> 1.29 | D35: =QUARTILE(Dados!H28:H39,1) -> 5.165 | E35: =QUARTILE(Dados!H28:H38,1) -> 5.795 | F35: =QUARTILE(Dados!H9:H39,1) -> 1.9 | G35: =QUARTILE(Dados!H2:H27,1) -> 1.68
A36: 3º quartil | B36: =QUARTILE(Dados!H2:H8,3) -> 4.59 | C36: =QUARTILE(Dados!H9:H27,3) -> 4.155 | D36: =QUARTILE(Dados!H28:H39,3) -> 18.38 | E36: =QUARTILE(Dados!H28:H38,3) -> 18.92 | F36: =QUARTILE(Dados!H9:H39,3) -> 6.64 | G36: =QUARTILE(Dados!H2:H27,3) -> 4.8
A37: Máximo | B37: =MAX(Dados!H2:H8) -> 6.3 | C37: =MAX(Dados!H9:H27) -> 8.07 | D37: =MAX(Dados!H28:H39) -> 22.16 | E37: =MAX(Dados!H28:H38) -> 22.16 | F37: =MAX(Dados!H9:H39) -> 22.16 | G37: =MAX(Dados!H2:H27) -> 8.07
A39: FRAÇÃO SOLÚVEL (% do total) | B39: Superfície (CV) | C39: Subsuperfície – Tab. 1 (F, S) | D39: Diques félsicos anômalos (Tab. 2) | E39: Diques s/ S3 16,20 | F39: Subsuperfície total | G39: Fundo: CV + Tab. 1
A40: n | B40: =COUNT(Dados!K2:K8) -> 6 | C40: =COUNT(Dados!K9:K27) -> 19 | D40: =COUNT(Dados!K28:K39) -> 11 | E40: =COUNT(Dados!K28:K38) -> 10 | F40: =COUNT(Dados!K9:K39) -> 30 | G40: =COUNT(Dados!K2:K27) -> 25
A41: Média | B41: =AVERAGE(Dados!K2:K8) -> 0.55174363 | C41: =AVERAGE(Dados!K9:K27) -> 0.70692581 | D41: =AVERAGE(Dados!K28:K39) -> 0.68577932 | E41: =AVERAGE(Dados!K28:K38) -> 0.65451829 | F41: =AVERAGE(Dados!K9:K39) -> 0.6991721 | G41: =AVERAGE(Dados!K2:K27) -> 0.66968208
A42: Mediana | B42: =MEDIAN(Dados!K2:K8) -> 0.61681818 | C42: =MEDIAN(Dados!K9:K27) -> 0.71157895 | D42: =MEDIAN(Dados!K28:K39) -> 0.71833333 | E42: =MEDIAN(Dados!K28:K38) -> 0.71614583 | F42: =MEDIAN(Dados!K9:K39) -> 0.71614583 | G42: =MEDIAN(Dados!K2:K27) -> 0.68961538
A43: Média geométrica | B43: =GEOMEAN(Dados!K2:K8) -> 0.51398388 | C43: =GEOMEAN(Dados!K9:K27) -> 0.69159248 | D43: =GEOMEAN(Dados!K28:K39) -> 0.63957205 | E43: =GEOMEAN(Dados!K28:K38) -> 0.611714 | F43: =GEOMEAN(Dados!K9:K39) -> 0.67204441 | G43: =GEOMEAN(Dados!K2:K27) -> 0.64404184
A44: Desvio padrão | B44: =STDEV(Dados!K2:K8) -> 0.20790413 | C44: =STDEV(Dados!K9:K27) -> 0.14736378 | D44: =STDEV(Dados!K28:K39) -> 0.20617969 | E44: =STDEV(Dados!K28:K38) -> 0.18785424 | F44: =STDEV(Dados!K9:K39) -> 0.16806254 | G44: =STDEV(Dados!K2:K27) -> 0.17282238
...

Sheet Testes
A1: Testes estatísticos não paramétricos (α = 0,05)
A2: Valores calculados em Python/SciPy (não recalculam no Excel). Testes não paramétricos escolhidos porque as distribuições são assimétricas e n é pequeno.
A4: Comparação | B4: Teste | C4: Estatística | D4: p-valor | E4: Significativo?
A5: U total: Superfície × Subsuperfície Tab. 1 | B5: Mann-Whitney U (bilateral) | C5: 64 | D5: 0.90745257 | E5: =IF(D5<0.05,"Sim","Não") -> Não
A6: U total: Superfície × Diques | B6: Mann-Whitney U (bilateral) | C6: 0 | D6: 0.00044731382 | E6: =IF(D6<0.05,"Sim","Não") -> Sim
A7: U total: Subsuperfície Tab. 1 × Diques | B7: Mann-Whitney U (bilateral) | C7: 7 | D7: 1.5296171e-05 | E7: =IF(D7<0.05,"Sim","Não") -> Sim
A8: U total: Superfície × Subsuperfície total | B8: Mann-Whitney U (bilateral) | C8: 64 | D8: 0.096946323 | E8: =IF(D8<0.05,"Sim","Não") -> Não
A9: % solúvel: Superfície × Subsuperfície Tab. 1 | B9: Mann-Whitney U (bilateral) | C9: 31 | D9: 0.10598532 | E9: =IF(D9<0.05,"Sim","Não") -> Não
A10: U fixo: Superfície × Subsuperfície Tab. 1 | B10: Mann-Whitney U (bilateral) | C10: 77 | D10: 0.22117448 | E10: =IF(D10<0.05,"Sim","Não") -> Não
A11: U fixo: Subsuperfície Tab. 1 × Diques | B11: Mann-Whitney U (bilateral) | C11: 20 | D11: 0.00030027412 | E11: =IF(D11<0.05,"Sim","Não") -> Sim
A12: U total × ThO2 nos diques (n=12) | B12: Spearman ρ | C12: 0.608 | D12: 0.035924779 | E12: =IF(D12<0.05,"Sim","Não") -> Sim
A13: U total × ThO2 nos diques sem S3 16,20 (n=11) | B13: Spearman ρ | C13: 0.673 | D13: 0.023300786 | E13: =IF(D13<0.05,"Sim","Não") -> Sim
A14: U total × profundidade (subsuperfície, n=31) | B14: Spearman ρ | C14: 0.198 | D14: 0.28608922 | E14: =IF(D14<0.05,"Sim","Não") -> Não

Sheet Gráfico
